[Fri Sep 04 04:34:11 2015] [error] [client 174.52.134.8] mod_wsgi (pid=24840): Target WSGI script '/sites/projects/checkin/backend/backend/wsgi.py' cannot be loaded as Python module.
[Fri Sep 04 04:34:11 2015] [error] [client 174.52.134.8] mod_wsgi (pid=24840): Exception occurred processing WSGI script '/sites/projects/checkin/backend/backend/wsgi.py'.
[Fri Sep 04 04:34:11 2015] [error] [client 174.52.134.8] Traceback (most recent call last):
[Fri Sep 04 04:34:11 2015] [error] [client 174.52.134.8]   File "/sites/projects/checkin/backend/backend/wsgi.py", line 12, in <module>
[Fri Sep 04 04:34:11 2015] [error] [client 174.52.134.8]     from django.core.wsgi import get_wsgi_application
[Fri Sep 04 04:34:11 2015] [error] [client 174.52.134.8] ImportError: No module named django.core.wsgi
[Fri Sep 04 04:34:11 2015] [error] [client 174.52.134.8] mod_wsgi (pid=24840): Target WSGI script '/sites/projects/checkin/backend/backend/wsgi.py' cannot be loaded as Python module.
[Fri Sep 04 04:34:11 2015] [error] [client 174.52.134.8] mod_wsgi (pid=24840): Exception occurred processing WSGI script '/sites/projects/checkin/backend/backend/wsgi.py'.
[Fri Sep 04 04:34:11 2015] [error] [client 174.52.134.8] Traceback (most recent call last):
[Fri Sep 04 04:34:11 2015] [error] [client 174.52.134.8]   File "/sites/projects/checkin/backend/backend/wsgi.py", line 12, in <module>
[Fri Sep 04 04:34:11 2015] [error] [client 174.52.134.8]     from django.core.wsgi import get_wsgi_application
[Fri Sep 04 04:34:11 2015] [error] [client 174.52.134.8] ImportError: No module named django.core.wsgi
[Fri Sep 04 04:45:00 2015] [error] [client 174.52.134.8] mod_wsgi (pid=25045): Target WSGI script '/sites/projects/checkin/backend/backend/wsgi.py' cannot be loaded as Python module.
[Fri Sep 04 04:45:00 2015] [error] [client 174.52.134.8] mod_wsgi (pid=25045): Exception occurred processing WSGI script '/sites/projects/checkin/backend/backend/wsgi.py'.
[Fri Sep 04 04:45:00 2015] [error] [client 174.52.134.8] Traceback (most recent call last):
[Fri Sep 04 04:45:00 2015] [error] [client 174.52.134.8]   File "/sites/projects/checkin/backend/backend/wsgi.py", line 12, in <module>
[Fri Sep 04 04:45:00 2015] [error] [client 174.52.134.8]     from django.core.wsgi import get_wsgi_application
[Fri Sep 04 04:45:00 2015] [error] [client 174.52.134.8] ImportError: No module named django.core.wsgi
[Fri Sep 04 04:45:00 2015] [error] [client 174.52.134.8] mod_wsgi (pid=25045): Target WSGI script '/sites/projects/checkin/backend/backend/wsgi.py' cannot be loaded as Python module.
[Fri Sep 04 04:45:00 2015] [error] [client 174.52.134.8] mod_wsgi (pid=25045): Exception occurred processing WSGI script '/sites/projects/checkin/backend/backend/wsgi.py'.
[Fri Sep 04 04:45:00 2015] [error] [client 174.52.134.8] Traceback (most recent call last):
[Fri Sep 04 04:45:00 2015] [error] [client 174.52.134.8]   File "/sites/projects/checkin/backend/backend/wsgi.py", line 12, in <module>
[Fri Sep 04 04:45:00 2015] [error] [client 174.52.134.8]     from django.core.wsgi import get_wsgi_application
[Fri Sep 04 04:45:00 2015] [error] [client 174.52.134.8] ImportError: No module named django.core.wsgi
[Fri Sep 04 04:55:48 2015] [error] [client 174.52.134.8] mod_wsgi (pid=25045): Target WSGI script '/sites/projects/checkin/backend/backend/wsgi.py' cannot be loaded as Python module.
[Fri Sep 04 04:55:48 2015] [error] [client 174.52.134.8] mod_wsgi (pid=25045): Exception occurred processing WSGI script '/sites/projects/checkin/backend/backend/wsgi.py'.
[Fri Sep 04 04:55:48 2015] [error] [client 174.52.134.8] Traceback (most recent call last):
[Fri Sep 04 04:55:48 2015] [error] [client 174.52.134.8]   File "/sites/projects/checkin/backend/backend/wsgi.py", line 12, in <module>
[Fri Sep 04 04:55:48 2015] [error] [client 174.52.134.8]     from django.core.wsgi import get_wsgi_application
[Fri Sep 04 04:55:48 2015] [error] [client 174.52.134.8] ImportError: No module named django.core.wsgi
[Fri Sep 04 04:55:48 2015] [error] [client 174.52.134.8] mod_wsgi (pid=25045): Target WSGI script '/sites/projects/checkin/backend/backend/wsgi.py' cannot be loaded as Python module.
[Fri Sep 04 04:55:48 2015] [error] [client 174.52.134.8] mod_wsgi (pid=25045): Exception occurred processing WSGI script '/sites/projects/checkin/backend/backend/wsgi.py'.
[Fri Sep 04 04:55:48 2015] [error] [client 174.52.134.8] Traceback (most recent call last):
[Fri Sep 04 04:55:48 2015] [error] [client 174.52.134.8]   File "/sites/projects/checkin/backend/backend/wsgi.py", line 12, in <module>
[Fri Sep 04 04:55:48 2015] [error] [client 174.52.134.8]     from django.core.wsgi import get_wsgi_application
[Fri Sep 04 04:55:48 2015] [error] [client 174.52.134.8] ImportError: No module named django.core.wsgi
[Fri Sep 04 04:56:18 2015] [error] [client 174.52.134.8] mod_wsgi (pid=25216): Target WSGI script '/sites/projects/checkin/backend/backend/wsgi.py' cannot be loaded as Python module.
[Fri Sep 04 04:56:18 2015] [error] [client 174.52.134.8] mod_wsgi (pid=25216): Exception occurred processing WSGI script '/sites/projects/checkin/backend/backend/wsgi.py'.
[Fri Sep 04 04:56:18 2015] [error] [client 174.52.134.8] Traceback (most recent call last):
[Fri Sep 04 04:56:18 2015] [error] [client 174.52.134.8]   File "/sites/projects/checkin/backend/backend/wsgi.py", line 12, in <module>
[Fri Sep 04 04:56:18 2015] [error] [client 174.52.134.8]     from django.core.wsgi import get_wsgi_application
[Fri Sep 04 04:56:18 2015] [error] [client 174.52.134.8] ImportError: No module named django.core.wsgi
[Fri Sep 04 04:56:18 2015] [error] [client 174.52.134.8] mod_wsgi (pid=25216): Target WSGI script '/sites/projects/checkin/backend/backend/wsgi.py' cannot be loaded as Python module.
[Fri Sep 04 04:56:18 2015] [error] [client 174.52.134.8] mod_wsgi (pid=25216): Exception occurred processing WSGI script '/sites/projects/checkin/backend/backend/wsgi.py'.
[Fri Sep 04 04:56:18 2015] [error] [client 174.52.134.8] Traceback (most recent call last):
[Fri Sep 04 04:56:18 2015] [error] [client 174.52.134.8]   File "/sites/projects/checkin/backend/backend/wsgi.py", line 12, in <module>
[Fri Sep 04 04:56:18 2015] [error] [client 174.52.134.8]     from django.core.wsgi import get_wsgi_application
[Fri Sep 04 04:56:18 2015] [error] [client 174.52.134.8] ImportError: No module named django.core.wsgi
[Fri Sep 04 05:03:30 2015] [error] [client 174.52.134.8] mod_wsgi (pid=25216): Target WSGI script '/sites/projects/checkin/backend/backend/wsgi.py' cannot be loaded as Python module.
[Fri Sep 04 05:03:30 2015] [error] [client 174.52.134.8] mod_wsgi (pid=25216): Exception occurred processing WSGI script '/sites/projects/checkin/backend/backend/wsgi.py'.
[Fri Sep 04 05:03:30 2015] [error] [client 174.52.134.8] Traceback (most recent call last):
[Fri Sep 04 05:03:30 2015] [error] [client 174.52.134.8]   File "/sites/projects/checkin/backend/backend/wsgi.py", line 12, in <module>
[Fri Sep 04 05:03:30 2015] [error] [client 174.52.134.8]     from django.core.wsgi import get_wsgi_application
[Fri Sep 04 05:03:30 2015] [error] [client 174.52.134.8] ImportError: No module named django.core.wsgi
[Fri Sep 04 05:03:30 2015] [error] [client 174.52.134.8] mod_wsgi (pid=25216): Target WSGI script '/sites/projects/checkin/backend/backend/wsgi.py' cannot be loaded as Python module.
[Fri Sep 04 05:03:30 2015] [error] [client 174.52.134.8] mod_wsgi (pid=25216): Exception occurred processing WSGI script '/sites/projects/checkin/backend/backend/wsgi.py'.
[Fri Sep 04 05:03:30 2015] [error] [client 174.52.134.8] Traceback (most recent call last):
[Fri Sep 04 05:03:30 2015] [error] [client 174.52.134.8]   File "/sites/projects/checkin/backend/backend/wsgi.py", line 12, in <module>
[Fri Sep 04 05:03:30 2015] [error] [client 174.52.134.8]     from django.core.wsgi import get_wsgi_application
[Fri Sep 04 05:03:30 2015] [error] [client 174.52.134.8] ImportError: No module named django.core.wsgi
[Fri Sep 04 05:03:48 2015] [error] [client 174.52.134.8] mod_wsgi (pid=25449): Target WSGI script '/sites/projects/checkin/backend/backend/wsgi.py' cannot be loaded as Python module.
[Fri Sep 04 05:03:48 2015] [error] [client 174.52.134.8] mod_wsgi (pid=25449): Exception occurred processing WSGI script '/sites/projects/checkin/backend/backend/wsgi.py'.
[Fri Sep 04 05:03:48 2015] [error] [client 174.52.134.8] Traceback (most recent call last):
[Fri Sep 04 05:03:48 2015] [error] [client 174.52.134.8]   File "/sites/projects/checkin/backend/backend/wsgi.py", line 12, in <module>
[Fri Sep 04 05:03:48 2015] [error] [client 174.52.134.8]     from django.core.wsgi import get_wsgi_application
[Fri Sep 04 05:03:48 2015] [error] [client 174.52.134.8] ImportError: No module named django.core.wsgi
[Fri Sep 04 05:03:48 2015] [error] [client 174.52.134.8] mod_wsgi (pid=25449): Target WSGI script '/sites/projects/checkin/backend/backend/wsgi.py' cannot be loaded as Python module.
[Fri Sep 04 05:03:48 2015] [error] [client 174.52.134.8] mod_wsgi (pid=25449): Exception occurred processing WSGI script '/sites/projects/checkin/backend/backend/wsgi.py'.
[Fri Sep 04 05:03:48 2015] [error] [client 174.52.134.8] Traceback (most recent call last):
[Fri Sep 04 05:03:48 2015] [error] [client 174.52.134.8]   File "/sites/projects/checkin/backend/backend/wsgi.py", line 12, in <module>
[Fri Sep 04 05:03:48 2015] [error] [client 174.52.134.8]     from django.core.wsgi import get_wsgi_application
[Fri Sep 04 05:03:48 2015] [error] [client 174.52.134.8] ImportError: No module named django.core.wsgi
[Fri Sep 04 05:03:51 2015] [error] [client 174.52.134.8] mod_wsgi (pid=25449): Target WSGI script '/sites/projects/checkin/backend/backend/wsgi.py' cannot be loaded as Python module.
[Fri Sep 04 05:03:51 2015] [error] [client 174.52.134.8] mod_wsgi (pid=25449): Exception occurred processing WSGI script '/sites/projects/checkin/backend/backend/wsgi.py'.
[Fri Sep 04 05:03:51 2015] [error] [client 174.52.134.8] Traceback (most recent call last):
[Fri Sep 04 05:03:51 2015] [error] [client 174.52.134.8]   File "/sites/projects/checkin/backend/backend/wsgi.py", line 12, in <module>
[Fri Sep 04 05:03:51 2015] [error] [client 174.52.134.8]     from django.core.wsgi import get_wsgi_application
[Fri Sep 04 05:03:51 2015] [error] [client 174.52.134.8] ImportError: No module named django.core.wsgi
[Fri Sep 04 05:03:51 2015] [error] [client 174.52.134.8] mod_wsgi (pid=25449): Target WSGI script '/sites/projects/checkin/backend/backend/wsgi.py' cannot be loaded as Python module.
[Fri Sep 04 05:03:51 2015] [error] [client 174.52.134.8] mod_wsgi (pid=25449): Exception occurred processing WSGI script '/sites/projects/checkin/backend/backend/wsgi.py'.
[Fri Sep 04 05:03:51 2015] [error] [client 174.52.134.8] Traceback (most recent call last):
[Fri Sep 04 05:03:51 2015] [error] [client 174.52.134.8]   File "/sites/projects/checkin/backend/backend/wsgi.py", line 12, in <module>
[Fri Sep 04 05:03:51 2015] [error] [client 174.52.134.8]     from django.core.wsgi import get_wsgi_application
[Fri Sep 04 05:03:51 2015] [error] [client 174.52.134.8] ImportError: No module named django.core.wsgi
[Fri Sep 04 07:07:49 2015] [error] [client 94.102.48.194] mod_wsgi (pid=25449): Target WSGI script '/sites/projects/checkin/backend/backend/wsgi.py' cannot be loaded as Python module.
[Fri Sep 04 07:07:49 2015] [error] [client 94.102.48.194] mod_wsgi (pid=25449): Exception occurred processing WSGI script '/sites/projects/checkin/backend/backend/wsgi.py'.
[Fri Sep 04 07:07:49 2015] [error] [client 94.102.48.194] Traceback (most recent call last):
[Fri Sep 04 07:07:49 2015] [error] [client 94.102.48.194]   File "/sites/projects/checkin/backend/backend/wsgi.py", line 12, in <module>
[Fri Sep 04 07:07:49 2015] [error] [client 94.102.48.194]     from django.core.wsgi import get_wsgi_application
[Fri Sep 04 07:07:49 2015] [error] [client 94.102.48.194] ImportError: No module named django.core.wsgi
[Fri Sep 04 15:14:57 2015] [error] [client 67.214.252.106] mod_wsgi (pid=1763): Target WSGI script '/sites/projects/checkin/backend/backend/wsgi.py' cannot be loaded as Python module.
[Fri Sep 04 15:14:57 2015] [error] [client 67.214.252.106] mod_wsgi (pid=1763): Exception occurred processing WSGI script '/sites/projects/checkin/backend/backend/wsgi.py'.
[Fri Sep 04 15:14:57 2015] [error] [client 67.214.252.106] Traceback (most recent call last):
[Fri Sep 04 15:14:57 2015] [error] [client 67.214.252.106]   File "/sites/projects/checkin/backend/backend/wsgi.py", line 12, in <module>
[Fri Sep 04 15:14:57 2015] [error] [client 67.214.252.106]     from django.core.wsgi import get_wsgi_application
[Fri Sep 04 15:14:57 2015] [error] [client 67.214.252.106] ImportError: No module named django.core.wsgi
[Fri Sep 04 15:14:58 2015] [error] [client 67.214.252.106] mod_wsgi (pid=1763): Target WSGI script '/sites/projects/checkin/backend/backend/wsgi.py' cannot be loaded as Python module.
[Fri Sep 04 15:14:58 2015] [error] [client 67.214.252.106] mod_wsgi (pid=1763): Exception occurred processing WSGI script '/sites/projects/checkin/backend/backend/wsgi.py'.
[Fri Sep 04 15:14:58 2015] [error] [client 67.214.252.106] Traceback (most recent call last):
[Fri Sep 04 15:14:58 2015] [error] [client 67.214.252.106]   File "/sites/projects/checkin/backend/backend/wsgi.py", line 12, in <module>
[Fri Sep 04 15:14:58 2015] [error] [client 67.214.252.106]     from django.core.wsgi import get_wsgi_application
[Fri Sep 04 15:14:58 2015] [error] [client 67.214.252.106] ImportError: No module named django.core.wsgi
[Fri Sep 04 15:15:03 2015] [error] [client 67.214.252.106] mod_wsgi (pid=1763): Target WSGI script '/sites/projects/checkin/backend/backend/wsgi.py' cannot be loaded as Python module.
[Fri Sep 04 15:15:03 2015] [error] [client 67.214.252.106] mod_wsgi (pid=1763): Exception occurred processing WSGI script '/sites/projects/checkin/backend/backend/wsgi.py'.
[Fri Sep 04 15:15:03 2015] [error] [client 67.214.252.106] Traceback (most recent call last):
[Fri Sep 04 15:15:03 2015] [error] [client 67.214.252.106]   File "/sites/projects/checkin/backend/backend/wsgi.py", line 12, in <module>
[Fri Sep 04 15:15:03 2015] [error] [client 67.214.252.106]     from django.core.wsgi import get_wsgi_application
[Fri Sep 04 15:15:03 2015] [error] [client 67.214.252.106] ImportError: No module named django.core.wsgi
[Fri Sep 04 15:15:03 2015] [error] [client 67.214.252.106] mod_wsgi (pid=1763): Target WSGI script '/sites/projects/checkin/backend/backend/wsgi.py' cannot be loaded as Python module.
[Fri Sep 04 15:15:03 2015] [error] [client 67.214.252.106] mod_wsgi (pid=1763): Exception occurred processing WSGI script '/sites/projects/checkin/backend/backend/wsgi.py'.
[Fri Sep 04 15:15:03 2015] [error] [client 67.214.252.106] Traceback (most recent call last):
[Fri Sep 04 15:15:03 2015] [error] [client 67.214.252.106]   File "/sites/projects/checkin/backend/backend/wsgi.py", line 12, in <module>
[Fri Sep 04 15:15:03 2015] [error] [client 67.214.252.106]     from django.core.wsgi import get_wsgi_application
[Fri Sep 04 15:15:03 2015] [error] [client 67.214.252.106] ImportError: No module named django.core.wsgi
[Fri Sep 11 21:36:22 2015] [error] [client 216.21.163.5] mod_wsgi (pid=12021): Target WSGI script '/sites/projects/checkin/backend/backend/wsgi.py' cannot be loaded as Python module.
[Fri Sep 11 21:36:22 2015] [error] [client 216.21.163.5] mod_wsgi (pid=12021): Exception occurred processing WSGI script '/sites/projects/checkin/backend/backend/wsgi.py'.
[Fri Sep 11 21:36:22 2015] [error] [client 216.21.163.5] Traceback (most recent call last):
[Fri Sep 11 21:36:22 2015] [error] [client 216.21.163.5]   File "/sites/projects/checkin/backend/backend/wsgi.py", line 16, in <module>
[Fri Sep 11 21:36:22 2015] [error] [client 216.21.163.5]     application = get_wsgi_application()
[Fri Sep 11 21:36:22 2015] [error] [client 216.21.163.5]   File "/sites/virtualenvs/checkin/lib/python2.7/site-packages/django/core/wsgi.py", line 14, in get_wsgi_application
[Fri Sep 11 21:36:22 2015] [error] [client 216.21.163.5]     django.setup()
[Fri Sep 11 21:36:22 2015] [error] [client 216.21.163.5]   File "/sites/virtualenvs/checkin/lib/python2.7/site-packages/django/__init__.py", line 18, in setup
[Fri Sep 11 21:36:22 2015] [error] [client 216.21.163.5]     apps.populate(settings.INSTALLED_APPS)
[Fri Sep 11 21:36:22 2015] [error] [client 216.21.163.5]   File "/sites/virtualenvs/checkin/lib/python2.7/site-packages/django/apps/registry.py", line 85, in populate
[Fri Sep 11 21:36:22 2015] [error] [client 216.21.163.5]     app_config = AppConfig.create(entry)
[Fri Sep 11 21:36:22 2015] [error] [client 216.21.163.5]   File "/sites/virtualenvs/checkin/lib/python2.7/site-packages/django/apps/config.py", line 86, in create
[Fri Sep 11 21:36:22 2015] [error] [client 216.21.163.5]     module = import_module(entry)
[Fri Sep 11 21:36:22 2015] [error] [client 216.21.163.5]   File "/usr/lib/python2.7/importlib/__init__.py", line 37, in import_module
[Fri Sep 11 21:36:22 2015] [error] [client 216.21.163.5]     __import__(name)
[Fri Sep 11 21:36:22 2015] [error] [client 216.21.163.5] ImportError: No module named oauth2_provider
[Fri Sep 11 21:36:40 2015] [error] [client 216.21.163.5] mod_wsgi (pid=12021): Target WSGI script '/sites/projects/checkin/backend/backend/wsgi.py' cannot be loaded as Python module.
[Fri Sep 11 21:36:40 2015] [error] [client 216.21.163.5] mod_wsgi (pid=12021): Exception occurred processing WSGI script '/sites/projects/checkin/backend/backend/wsgi.py'.
[Fri Sep 11 21:36:40 2015] [error] [client 216.21.163.5] Traceback (most recent call last):
[Fri Sep 11 21:36:40 2015] [error] [client 216.21.163.5]   File "/sites/projects/checkin/backend/backend/wsgi.py", line 16, in <module>
[Fri Sep 11 21:36:40 2015] [error] [client 216.21.163.5]     application = get_wsgi_application()
[Fri Sep 11 21:36:40 2015] [error] [client 216.21.163.5]   File "/sites/virtualenvs/checkin/lib/python2.7/site-packages/django/core/wsgi.py", line 14, in get_wsgi_application
[Fri Sep 11 21:36:40 2015] [error] [client 216.21.163.5]     django.setup()
[Fri Sep 11 21:36:40 2015] [error] [client 216.21.163.5]   File "/sites/virtualenvs/checkin/lib/python2.7/site-packages/django/__init__.py", line 18, in setup
[Fri Sep 11 21:36:40 2015] [error] [client 216.21.163.5]     apps.populate(settings.INSTALLED_APPS)
[Fri Sep 11 21:36:40 2015] [error] [client 216.21.163.5]   File "/sites/virtualenvs/checkin/lib/python2.7/site-packages/django/apps/registry.py", line 78, in populate
[Fri Sep 11 21:36:40 2015] [error] [client 216.21.163.5]     raise RuntimeError("populate() isn't reentrant")
[Fri Sep 11 21:36:40 2015] [error] [client 216.21.163.5] RuntimeError: populate() isn't reentrant
[Fri Sep 11 21:36:44 2015] [error] [client 216.21.163.5] mod_wsgi (pid=12021): Target WSGI script '/sites/projects/checkin/backend/backend/wsgi.py' cannot be loaded as Python module.
[Fri Sep 11 21:36:44 2015] [error] [client 216.21.163.5] mod_wsgi (pid=12021): Exception occurred processing WSGI script '/sites/projects/checkin/backend/backend/wsgi.py'.
[Fri Sep 11 21:36:44 2015] [error] [client 216.21.163.5] Traceback (most recent call last):
[Fri Sep 11 21:36:44 2015] [error] [client 216.21.163.5]   File "/sites/projects/checkin/backend/backend/wsgi.py", line 16, in <module>
[Fri Sep 11 21:36:44 2015] [error] [client 216.21.163.5]     application = get_wsgi_application()
[Fri Sep 11 21:36:44 2015] [error] [client 216.21.163.5]   File "/sites/virtualenvs/checkin/lib/python2.7/site-packages/django/core/wsgi.py", line 14, in get_wsgi_application
[Fri Sep 11 21:36:44 2015] [error] [client 216.21.163.5]     django.setup()
[Fri Sep 11 21:36:44 2015] [error] [client 216.21.163.5]   File "/sites/virtualenvs/checkin/lib/python2.7/site-packages/django/__init__.py", line 18, in setup
[Fri Sep 11 21:36:44 2015] [error] [client 216.21.163.5]     apps.populate(settings.INSTALLED_APPS)
[Fri Sep 11 21:36:44 2015] [error] [client 216.21.163.5]   File "/sites/virtualenvs/checkin/lib/python2.7/site-packages/django/apps/registry.py", line 78, in populate
[Fri Sep 11 21:36:44 2015] [error] [client 216.21.163.5]     raise RuntimeError("populate() isn't reentrant")
[Fri Sep 11 21:36:44 2015] [error] [client 216.21.163.5] RuntimeError: populate() isn't reentrant
[Fri Sep 11 21:37:33 2015] [error] [client 216.21.163.5] mod_wsgi (pid=12021): Target WSGI script '/sites/projects/checkin/backend/backend/wsgi.py' cannot be loaded as Python module.
[Fri Sep 11 21:37:33 2015] [error] [client 216.21.163.5] mod_wsgi (pid=12021): Exception occurred processing WSGI script '/sites/projects/checkin/backend/backend/wsgi.py'.
[Fri Sep 11 21:37:33 2015] [error] [client 216.21.163.5] Traceback (most recent call last):
[Fri Sep 11 21:37:33 2015] [error] [client 216.21.163.5]   File "/sites/projects/checkin/backend/backend/wsgi.py", line 16, in <module>
[Fri Sep 11 21:37:33 2015] [error] [client 216.21.163.5]     application = get_wsgi_application()
[Fri Sep 11 21:37:33 2015] [error] [client 216.21.163.5]   File "/sites/virtualenvs/checkin/lib/python2.7/site-packages/django/core/wsgi.py", line 14, in get_wsgi_application
[Fri Sep 11 21:37:33 2015] [error] [client 216.21.163.5]     django.setup()
[Fri Sep 11 21:37:33 2015] [error] [client 216.21.163.5]   File "/sites/virtualenvs/checkin/lib/python2.7/site-packages/django/__init__.py", line 18, in setup
[Fri Sep 11 21:37:33 2015] [error] [client 216.21.163.5]     apps.populate(settings.INSTALLED_APPS)
[Fri Sep 11 21:37:33 2015] [error] [client 216.21.163.5]   File "/sites/virtualenvs/checkin/lib/python2.7/site-packages/django/apps/registry.py", line 78, in populate
[Fri Sep 11 21:37:33 2015] [error] [client 216.21.163.5]     raise RuntimeError("populate() isn't reentrant")
[Fri Sep 11 21:37:33 2015] [error] [client 216.21.163.5] RuntimeError: populate() isn't reentrant
[Fri Sep 11 21:37:59 2015] [error] [client 216.21.163.5] mod_wsgi (pid=12021): Target WSGI script '/sites/projects/checkin/backend/backend/wsgi.py' cannot be loaded as Python module.
[Fri Sep 11 21:37:59 2015] [error] [client 216.21.163.5] mod_wsgi (pid=12021): Exception occurred processing WSGI script '/sites/projects/checkin/backend/backend/wsgi.py'.
[Fri Sep 11 21:37:59 2015] [error] [client 216.21.163.5] Traceback (most recent call last):
[Fri Sep 11 21:37:59 2015] [error] [client 216.21.163.5]   File "/sites/projects/checkin/backend/backend/wsgi.py", line 16, in <module>
[Fri Sep 11 21:37:59 2015] [error] [client 216.21.163.5]     application = get_wsgi_application()
[Fri Sep 11 21:37:59 2015] [error] [client 216.21.163.5]   File "/sites/virtualenvs/checkin/lib/python2.7/site-packages/django/core/wsgi.py", line 14, in get_wsgi_application
[Fri Sep 11 21:37:59 2015] [error] [client 216.21.163.5]     django.setup()
[Fri Sep 11 21:37:59 2015] [error] [client 216.21.163.5]   File "/sites/virtualenvs/checkin/lib/python2.7/site-packages/django/__init__.py", line 18, in setup
[Fri Sep 11 21:37:59 2015] [error] [client 216.21.163.5]     apps.populate(settings.INSTALLED_APPS)
[Fri Sep 11 21:37:59 2015] [error] [client 216.21.163.5]   File "/sites/virtualenvs/checkin/lib/python2.7/site-packages/django/apps/registry.py", line 78, in populate
[Fri Sep 11 21:37:59 2015] [error] [client 216.21.163.5]     raise RuntimeError("populate() isn't reentrant")
[Fri Sep 11 21:37:59 2015] [error] [client 216.21.163.5] RuntimeError: populate() isn't reentrant
[Fri Sep 11 21:38:03 2015] [error] [client 216.21.163.5] mod_wsgi (pid=12021): Target WSGI script '/sites/projects/checkin/backend/backend/wsgi.py' cannot be loaded as Python module.
[Fri Sep 11 21:38:03 2015] [error] [client 216.21.163.5] mod_wsgi (pid=12021): Exception occurred processing WSGI script '/sites/projects/checkin/backend/backend/wsgi.py'.
[Fri Sep 11 21:38:03 2015] [error] [client 216.21.163.5] Traceback (most recent call last):
[Fri Sep 11 21:38:03 2015] [error] [client 216.21.163.5]   File "/sites/projects/checkin/backend/backend/wsgi.py", line 16, in <module>
[Fri Sep 11 21:38:03 2015] [error] [client 216.21.163.5]     application = get_wsgi_application()
[Fri Sep 11 21:38:03 2015] [error] [client 216.21.163.5]   File "/sites/virtualenvs/checkin/lib/python2.7/site-packages/django/core/wsgi.py", line 14, in get_wsgi_application
[Fri Sep 11 21:38:03 2015] [error] [client 216.21.163.5]     django.setup()
[Fri Sep 11 21:38:03 2015] [error] [client 216.21.163.5]   File "/sites/virtualenvs/checkin/lib/python2.7/site-packages/django/__init__.py", line 18, in setup
[Fri Sep 11 21:38:03 2015] [error] [client 216.21.163.5]     apps.populate(settings.INSTALLED_APPS)
[Fri Sep 11 21:38:03 2015] [error] [client 216.21.163.5]   File "/sites/virtualenvs/checkin/lib/python2.7/site-packages/django/apps/registry.py", line 78, in populate
[Fri Sep 11 21:38:03 2015] [error] [client 216.21.163.5]     raise RuntimeError("populate() isn't reentrant")
[Fri Sep 11 21:38:03 2015] [error] [client 216.21.163.5] RuntimeError: populate() isn't reentrant
[Fri Sep 18 18:21:05 2015] [error] {u'username': u'steve', u'password': u'steve', u'first_name': u'steve', u'last_name': u'bobo', u'email': u'steve@steve.com'}
[Fri Sep 18 18:21:05 2015] [error] UserSerializer(context={u'view': <main.views.UserRegistration object>, u'request': <rest_framework.request.Request object>, u'format': None}, data={u'username': u'steve', u'password': u'steve', u'first_name': u'steve', u'last_name': u'bobo', u'email': u'steve@steve.com'}):
[Fri Sep 18 18:21:05 2015] [error]     id = IntegerField(label='ID', read_only=True)
[Fri Sep 18 18:21:05 2015] [error]     username = CharField(help_text='Required. 30 characters or fewer. Letters, digits and @/./+/-/_ only.', max_length=30, validators=[<django.core.validators.RegexValidator object>, <UniqueValidator(queryset=User.objects.all())>])
[Fri Sep 18 18:21:05 2015] [error]     email = EmailField(allow_blank=True, label='Email address', max_length=254, required=False)
[Fri Sep 18 18:21:05 2015] [error]     first_name = CharField(allow_blank=True, max_length=30, required=False)
[Fri Sep 18 18:21:05 2015] [error]     last_name = CharField(allow_blank=True, max_length=30, required=False)
[Fri Sep 18 18:21:05 2015] [error]     info = InfoSerializer(required=False):
[Fri Sep 18 18:21:05 2015] [error]         user = ModelField(model_field=<django.db.models.fields.related.OneToOneField: user>, validators=[<UniqueValidator(queryset=Info.objects.all())>])
[Fri Sep 18 18:21:05 2015] [error]         phone_number = CharField(allow_blank=True, allow_null=True, max_length=30, required=False)
[Fri Sep 18 18:21:05 2015] [error]         profile_pic = Base64ImageField(max_length=None, required=False, use_url=True)
[Fri Sep 18 18:21:05 2015] [error]         family = PrimaryKeyRelatedField(allow_null=True, queryset=Family.objects.all(), required=False)
[Fri Sep 18 18:21:05 2015] [error]     locations = PrimaryKeyRelatedField(many=True, read_only=True)
[Fri Sep 18 18:21:05 2015] [error]     checkins = PrimaryKeyRelatedField(many=True, read_only=True)
[Fri Sep 18 18:21:05 2015] [error]     password = CharField(max_length=128)
[Mon Sep 21 22:10:12 2015] [error] [client 216.21.163.5] mod_wsgi (pid=22720): Target WSGI script '/sites/projects/checkin/backend/backend/wsgi.py' cannot be loaded as Python module.
[Mon Sep 21 22:10:12 2015] [error] [client 216.21.163.5] mod_wsgi (pid=22720): Exception occurred processing WSGI script '/sites/projects/checkin/backend/backend/wsgi.py'.
[Mon Sep 21 22:10:12 2015] [error] [client 216.21.163.5] Traceback (most recent call last):
[Mon Sep 21 22:10:12 2015] [error] [client 216.21.163.5]   File "/sites/projects/checkin/backend/backend/wsgi.py", line 16, in <module>
[Mon Sep 21 22:10:12 2015] [error] [client 216.21.163.5]     application = get_wsgi_application()
[Mon Sep 21 22:10:12 2015] [error] [client 216.21.163.5]   File "/sites/virtualenvs/checkin/lib/python2.7/site-packages/django/core/wsgi.py", line 14, in get_wsgi_application
[Mon Sep 21 22:10:12 2015] [error] [client 216.21.163.5]     django.setup()
[Mon Sep 21 22:10:12 2015] [error] [client 216.21.163.5]   File "/sites/virtualenvs/checkin/lib/python2.7/site-packages/django/__init__.py", line 18, in setup
[Mon Sep 21 22:10:12 2015] [error] [client 216.21.163.5]     apps.populate(settings.INSTALLED_APPS)
[Mon Sep 21 22:10:12 2015] [error] [client 216.21.163.5]   File "/sites/virtualenvs/checkin/lib/python2.7/site-packages/django/apps/registry.py", line 85, in populate
[Mon Sep 21 22:10:12 2015] [error] [client 216.21.163.5]     app_config = AppConfig.create(entry)
[Mon Sep 21 22:10:12 2015] [error] [client 216.21.163.5]   File "/sites/virtualenvs/checkin/lib/python2.7/site-packages/django/apps/config.py", line 112, in create
[Mon Sep 21 22:10:12 2015] [error] [client 216.21.163.5]     mod = import_module(mod_path)
[Mon Sep 21 22:10:12 2015] [error] [client 216.21.163.5]   File "/usr/lib/python2.7/importlib/__init__.py", line 37, in import_module
[Mon Sep 21 22:10:12 2015] [error] [client 216.21.163.5]     __import__(name)
[Mon Sep 21 22:10:12 2015] [error] [client 216.21.163.5] ImportError: No module named social.apps.django_app
[Mon Sep 21 22:10:21 2015] [error] [client 216.21.163.5] mod_wsgi (pid=22720): Target WSGI script '/sites/projects/checkin/backend/backend/wsgi.py' cannot be loaded as Python module.
[Mon Sep 21 22:10:21 2015] [error] [client 216.21.163.5] mod_wsgi (pid=22720): Exception occurred processing WSGI script '/sites/projects/checkin/backend/backend/wsgi.py'.
[Mon Sep 21 22:10:21 2015] [error] [client 216.21.163.5] Traceback (most recent call last):
[Mon Sep 21 22:10:21 2015] [error] [client 216.21.163.5]   File "/sites/projects/checkin/backend/backend/wsgi.py", line 16, in <module>
[Mon Sep 21 22:10:21 2015] [error] [client 216.21.163.5]     application = get_wsgi_application()
[Mon Sep 21 22:10:21 2015] [error] [client 216.21.163.5]   File "/sites/virtualenvs/checkin/lib/python2.7/site-packages/django/core/wsgi.py", line 14, in get_wsgi_application
[Mon Sep 21 22:10:21 2015] [error] [client 216.21.163.5]     django.setup()
[Mon Sep 21 22:10:21 2015] [error] [client 216.21.163.5]   File "/sites/virtualenvs/checkin/lib/python2.7/site-packages/django/__init__.py", line 18, in setup
[Mon Sep 21 22:10:21 2015] [error] [client 216.21.163.5]     apps.populate(settings.INSTALLED_APPS)
[Mon Sep 21 22:10:21 2015] [error] [client 216.21.163.5]   File "/sites/virtualenvs/checkin/lib/python2.7/site-packages/django/apps/registry.py", line 78, in populate
[Mon Sep 21 22:10:21 2015] [error] [client 216.21.163.5]     raise RuntimeError("populate() isn't reentrant")
[Mon Sep 21 22:10:21 2015] [error] [client 216.21.163.5] RuntimeError: populate() isn't reentrant
[Mon Sep 21 22:10:27 2015] [error] [client 216.21.163.5] mod_wsgi (pid=22720): Target WSGI script '/sites/projects/checkin/backend/backend/wsgi.py' cannot be loaded as Python module.
[Mon Sep 21 22:10:27 2015] [error] [client 216.21.163.5] mod_wsgi (pid=22720): Exception occurred processing WSGI script '/sites/projects/checkin/backend/backend/wsgi.py'.
[Mon Sep 21 22:10:27 2015] [error] [client 216.21.163.5] Traceback (most recent call last):
[Mon Sep 21 22:10:27 2015] [error] [client 216.21.163.5]   File "/sites/projects/checkin/backend/backend/wsgi.py", line 16, in <module>
[Mon Sep 21 22:10:27 2015] [error] [client 216.21.163.5]     application = get_wsgi_application()
[Mon Sep 21 22:10:27 2015] [error] [client 216.21.163.5]   File "/sites/virtualenvs/checkin/lib/python2.7/site-packages/django/core/wsgi.py", line 14, in get_wsgi_application
[Mon Sep 21 22:10:27 2015] [error] [client 216.21.163.5]     django.setup()
[Mon Sep 21 22:10:27 2015] [error] [client 216.21.163.5]   File "/sites/virtualenvs/checkin/lib/python2.7/site-packages/django/__init__.py", line 18, in setup
[Mon Sep 21 22:10:27 2015] [error] [client 216.21.163.5]     apps.populate(settings.INSTALLED_APPS)
[Mon Sep 21 22:10:27 2015] [error] [client 216.21.163.5]   File "/sites/virtualenvs/checkin/lib/python2.7/site-packages/django/apps/registry.py", line 78, in populate
[Mon Sep 21 22:10:27 2015] [error] [client 216.21.163.5]     raise RuntimeError("populate() isn't reentrant")
[Mon Sep 21 22:10:27 2015] [error] [client 216.21.163.5] RuntimeError: populate() isn't reentrant
